[2023-08-24T18:07:51.355+0000] {taskinstance.py:1165} INFO - Dependencies all met for <TaskInstance: nikeProducts_dag.step_2_task manual__2023-08-24T18:07:48.232577+00:00 [queued]>
[2023-08-24T18:07:51.362+0000] {taskinstance.py:1165} INFO - Dependencies all met for <TaskInstance: nikeProducts_dag.step_2_task manual__2023-08-24T18:07:48.232577+00:00 [queued]>
[2023-08-24T18:07:51.362+0000] {taskinstance.py:1362} INFO - 
--------------------------------------------------------------------------------
[2023-08-24T18:07:51.363+0000] {taskinstance.py:1363} INFO - Starting attempt 1 of 2
[2023-08-24T18:07:51.363+0000] {taskinstance.py:1364} INFO - 
--------------------------------------------------------------------------------
[2023-08-24T18:07:51.371+0000] {taskinstance.py:1383} INFO - Executing <Task(PythonOperator): step_2_task> on 2023-08-24 18:07:48.232577+00:00
[2023-08-24T18:07:51.376+0000] {standard_task_runner.py:55} INFO - Started process 42908 to run task
[2023-08-24T18:07:51.379+0000] {standard_task_runner.py:82} INFO - Running: ['***', 'tasks', 'run', 'nikeProducts_dag', 'step_2_task', 'manual__2023-08-24T18:07:48.232577+00:00', '--job-id', '82', '--raw', '--subdir', 'DAGS_FOLDER/nikeProducts_dag.py', '--cfg-path', '/tmp/tmpvw96gowd']
[2023-08-24T18:07:51.381+0000] {standard_task_runner.py:83} INFO - Job 82: Subtask step_2_task
[2023-08-24T18:07:51.430+0000] {task_command.py:376} INFO - Running <TaskInstance: nikeProducts_dag.step_2_task manual__2023-08-24T18:07:48.232577+00:00 [running]> on host 5879ed69cda2
[2023-08-24T18:07:51.477+0000] {taskinstance.py:1592} INFO - Exporting the following env vars:
AIRFLOW_CTX_DAG_OWNER=***
AIRFLOW_CTX_DAG_ID=nikeProducts_dag
AIRFLOW_CTX_TASK_ID=step_2_task
AIRFLOW_CTX_EXECUTION_DATE=2023-08-24T18:07:48.232577+00:00
AIRFLOW_CTX_TRY_NUMBER=1
AIRFLOW_CTX_DAG_RUN_ID=manual__2023-08-24T18:07:48.232577+00:00
[2023-08-24T18:07:51.486+0000] {logging_mixin.py:120} INFO - products_etl.csv
[2023-08-24T18:07:51.563+0000] {taskinstance.py:1851} ERROR - Task failed with exception
Traceback (most recent call last):
  File "/home/airflow/.local/lib/python3.7/site-packages/pandas/core/indexes/base.py", line 3361, in get_loc
    return self._engine.get_loc(casted_key)
  File "pandas/_libs/index.pyx", line 76, in pandas._libs.index.IndexEngine.get_loc
  File "pandas/_libs/index.pyx", line 108, in pandas._libs.index.IndexEngine.get_loc
  File "pandas/_libs/hashtable_class_helper.pxi", line 5198, in pandas._libs.hashtable.PyObjectHashTable.get_item
  File "pandas/_libs/hashtable_class_helper.pxi", line 5206, in pandas._libs.hashtable.PyObjectHashTable.get_item
KeyError: 'rating'

The above exception was the direct cause of the following exception:

Traceback (most recent call last):
  File "/home/airflow/.local/lib/python3.7/site-packages/airflow/operators/python.py", line 175, in execute
    return_value = self.execute_callable()
  File "/home/airflow/.local/lib/python3.7/site-packages/airflow/operators/python.py", line 193, in execute_callable
    return self.python_callable(*self.op_args, **self.op_kwargs)
  File "/opt/airflow/dags/scripts/transform_data.py", line 15, in main
    df['rating'].fillna(0, inplace=True)
  File "/home/airflow/.local/lib/python3.7/site-packages/pandas/core/frame.py", line 3458, in __getitem__
    indexer = self.columns.get_loc(key)
  File "/home/airflow/.local/lib/python3.7/site-packages/pandas/core/indexes/base.py", line 3363, in get_loc
    raise KeyError(key) from err
KeyError: 'rating'
[2023-08-24T18:07:51.575+0000] {taskinstance.py:1406} INFO - Marking task as UP_FOR_RETRY. dag_id=nikeProducts_dag, task_id=step_2_task, execution_date=20230824T180748, start_date=20230824T180751, end_date=20230824T180751
[2023-08-24T18:07:51.582+0000] {standard_task_runner.py:105} ERROR - Failed to execute job 82 for task step_2_task ('rating'; 42908)
[2023-08-24T18:07:51.593+0000] {local_task_job.py:164} INFO - Task exited with return code 1
[2023-08-24T18:07:51.612+0000] {local_task_job.py:273} INFO - 0 downstream tasks scheduled from follow-on schedule check
